<mujoco model="mars_hexapod">
  <!--
    MARS — Modular Autonomous Robotic System — MuJoCo Model
    Generated by simulation/hexapod_model.py

    Coordinate frame: X=right, Y=forward, Z=up
    Robot body frame:  X=right, Y=up, Z=forward
    Mapping: robot(X,Y,Z) → mujoco(X,Z,Y)

    Total mass: 2.1 kg  (body 0.948 + 18 servos × 0.064 kg)
    Servo: HTS-35H, 3.43 N·m stall, 333°/s
    Standing: 130mm outward, 150mm below hip
    Standing angles: femur=78.0°, tibia=-73.7°
  -->

  <compiler angle="radian" meshdir="meshes"/>

  <option timestep="0.002" gravity="0 0 -9.81" integrator="implicit">
    <flag contact="enable"/>
  </option>

  <visual>
    <headlight ambient="0.3 0.3 0.3" diffuse="0.6 0.6 0.6"/>
    <rgba haze="0.15 0.25 0.35 1"/>
    <global offwidth="1920" offheight="1080"/>
  </visual>

  <default>
    <joint damping="0.5" limited="true" armature="0.01"/>
    <geom condim="3" friction="0.8 0.005 0.0001" margin="0.001"/>
  </default>

  <asset>
    <mesh name="body_mesh" file="body.stl" smoothnormal="true"/>
    <texture name="grid" type="2d" builtin="checker" width="512" height="512"
             rgb1="0.8 0.8 0.8" rgb2="0.6 0.6 0.6"/>
    <material name="floor_mat" texture="grid" texrepeat="8 8" reflectance="0.2"/>
  </asset>

  <worldbody>
    <light directional="true" pos="0 0 3" dir="0 0.3 -1" castshadow="true"/>
    <camera name="tracking" pos="0.6 -0.4 0.4" xyaxes="0.5 0.866 0 -0.2 0.115 0.97"
            mode="trackcom"/>
    <camera name="side" pos="0.5 0 0.3" xyaxes="0 1 0 -0.5 0 0.866"
            mode="trackcom"/>
    <camera name="top" pos="0 0 1.0" xyaxes="1 0 0 0 1 0" mode="trackcom"/>
    <geom name="floor" type="plane" size="2 2 0.05" material="floor_mat"/>

    <body name="body" pos="0 0 0.1500">
      <freejoint name="root"/>
      <site name="body_imu" pos="0 0 0" type="box" size="0.01 0.01 0.01"
            rgba="0 1 0 0.3"/>
      <geom name="body_shell" type="mesh" mesh="body_mesh"
            rgba="0.2 0.2 0.4 1" mass="0.9480"/>

      <!-- LF leg -->
      <body name="LF_coxa" pos="-0.065596 0.088163 0" euler="0 0 0.639669">
        <joint name="LF_coxa" type="hinge" axis="0 0 1"
               range="-2.0944 2.0944"/>
        <geom name="LF_coxa" type="capsule"
              fromto="0 0 0 0 0.041700 0" size="0.012"
              rgba="0.9 0.6 0.1 1" mass="0.064"/>

        <body name="LF_femur" pos="0 0.041700 0">
          <joint name="LF_femur" type="hinge" axis="1 0 0"
                 range="-2.0944 2.0944"/>
          <geom name="LF_femur" type="capsule"
                fromto="0 0 0 0 0 -0.080000" size="0.01"
                rgba="0.8 0.7 0.2 1" mass="0.064"/>

          <body name="LF_tibia" pos="0 0 -0.080000">
            <joint name="LF_tibia" type="hinge" axis="1 0 0"
                   range="-2.0944 2.0944"/>
            <geom name="LF_tibia" type="capsule"
                  fromto="0 0 0 0 0 -0.133780" size="0.008"
                  rgba="0.7 0.3 0.2 1" mass="0.064"/>
            <geom name="LF_foot" type="sphere"
                  pos="0 0 -0.133780" size="0.008"
                  rgba="0.9 0.9 0.9 1" mass="0.001"/>
            <site name="LF_foot_site" pos="0 0 -0.133780"
                  type="sphere" size="0.0240" rgba="1 0 0 0.3"/>
          </body>
        </body>
      </body>
      <!-- LM leg -->
      <body name="LM_coxa" pos="-0.086000 0.000000 0" euler="0 0 1.570796">
        <joint name="LM_coxa" type="hinge" axis="0 0 1"
               range="-2.0944 2.0944"/>
        <geom name="LM_coxa" type="capsule"
              fromto="0 0 0 0 0.041700 0" size="0.012"
              rgba="0.9 0.6 0.1 1" mass="0.064"/>

        <body name="LM_femur" pos="0 0.041700 0">
          <joint name="LM_femur" type="hinge" axis="1 0 0"
                 range="-2.0944 2.0944"/>
          <geom name="LM_femur" type="capsule"
                fromto="0 0 0 0 0 -0.080000" size="0.01"
                rgba="0.8 0.7 0.2 1" mass="0.064"/>

          <body name="LM_tibia" pos="0 0 -0.080000">
            <joint name="LM_tibia" type="hinge" axis="1 0 0"
                   range="-2.0944 2.0944"/>
            <geom name="LM_tibia" type="capsule"
                  fromto="0 0 0 0 0 -0.133780" size="0.008"
                  rgba="0.7 0.3 0.2 1" mass="0.064"/>
            <geom name="LM_foot" type="sphere"
                  pos="0 0 -0.133780" size="0.008"
                  rgba="0.9 0.9 0.9 1" mass="0.001"/>
            <site name="LM_foot_site" pos="0 0 -0.133780"
                  type="sphere" size="0.0240" rgba="1 0 0 0.3"/>
          </body>
        </body>
      </body>
      <!-- LR leg -->
      <body name="LR_coxa" pos="-0.065596 -0.088163 0" euler="0 0 2.501923">
        <joint name="LR_coxa" type="hinge" axis="0 0 1"
               range="-2.0944 2.0944"/>
        <geom name="LR_coxa" type="capsule"
              fromto="0 0 0 0 0.041700 0" size="0.012"
              rgba="0.9 0.6 0.1 1" mass="0.064"/>

        <body name="LR_femur" pos="0 0.041700 0">
          <joint name="LR_femur" type="hinge" axis="1 0 0"
                 range="-2.0944 2.0944"/>
          <geom name="LR_femur" type="capsule"
                fromto="0 0 0 0 0 -0.080000" size="0.01"
                rgba="0.8 0.7 0.2 1" mass="0.064"/>

          <body name="LR_tibia" pos="0 0 -0.080000">
            <joint name="LR_tibia" type="hinge" axis="1 0 0"
                   range="-2.0944 2.0944"/>
            <geom name="LR_tibia" type="capsule"
                  fromto="0 0 0 0 0 -0.133780" size="0.008"
                  rgba="0.7 0.3 0.2 1" mass="0.064"/>
            <geom name="LR_foot" type="sphere"
                  pos="0 0 -0.133780" size="0.008"
                  rgba="0.9 0.9 0.9 1" mass="0.001"/>
            <site name="LR_foot_site" pos="0 0 -0.133780"
                  type="sphere" size="0.0240" rgba="1 0 0 0.3"/>
          </body>
        </body>
      </body>
      <!-- RF leg -->
      <body name="RF_coxa" pos="0.065596 0.088163 0" euler="0 0 -0.639669">
        <joint name="RF_coxa" type="hinge" axis="0 0 1"
               range="-2.0944 2.0944"/>
        <geom name="RF_coxa" type="capsule"
              fromto="0 0 0 0 0.041700 0" size="0.012"
              rgba="0.9 0.6 0.1 1" mass="0.064"/>

        <body name="RF_femur" pos="0 0.041700 0">
          <joint name="RF_femur" type="hinge" axis="1 0 0"
                 range="-2.0944 2.0944"/>
          <geom name="RF_femur" type="capsule"
                fromto="0 0 0 0 0 -0.080000" size="0.01"
                rgba="0.8 0.7 0.2 1" mass="0.064"/>

          <body name="RF_tibia" pos="0 0 -0.080000">
            <joint name="RF_tibia" type="hinge" axis="1 0 0"
                   range="-2.0944 2.0944"/>
            <geom name="RF_tibia" type="capsule"
                  fromto="0 0 0 0 0 -0.133780" size="0.008"
                  rgba="0.7 0.3 0.2 1" mass="0.064"/>
            <geom name="RF_foot" type="sphere"
                  pos="0 0 -0.133780" size="0.008"
                  rgba="0.9 0.9 0.9 1" mass="0.001"/>
            <site name="RF_foot_site" pos="0 0 -0.133780"
                  type="sphere" size="0.0240" rgba="1 0 0 0.3"/>
          </body>
        </body>
      </body>
      <!-- RM leg -->
      <body name="RM_coxa" pos="0.086000 0.000000 0" euler="0 0 -1.570796">
        <joint name="RM_coxa" type="hinge" axis="0 0 1"
               range="-2.0944 2.0944"/>
        <geom name="RM_coxa" type="capsule"
              fromto="0 0 0 0 0.041700 0" size="0.012"
              rgba="0.9 0.6 0.1 1" mass="0.064"/>

        <body name="RM_femur" pos="0 0.041700 0">
          <joint name="RM_femur" type="hinge" axis="1 0 0"
                 range="-2.0944 2.0944"/>
          <geom name="RM_femur" type="capsule"
                fromto="0 0 0 0 0 -0.080000" size="0.01"
                rgba="0.8 0.7 0.2 1" mass="0.064"/>

          <body name="RM_tibia" pos="0 0 -0.080000">
            <joint name="RM_tibia" type="hinge" axis="1 0 0"
                   range="-2.0944 2.0944"/>
            <geom name="RM_tibia" type="capsule"
                  fromto="0 0 0 0 0 -0.133780" size="0.008"
                  rgba="0.7 0.3 0.2 1" mass="0.064"/>
            <geom name="RM_foot" type="sphere"
                  pos="0 0 -0.133780" size="0.008"
                  rgba="0.9 0.9 0.9 1" mass="0.001"/>
            <site name="RM_foot_site" pos="0 0 -0.133780"
                  type="sphere" size="0.0240" rgba="1 0 0 0.3"/>
          </body>
        </body>
      </body>
      <!-- RR leg -->
      <body name="RR_coxa" pos="0.065596 -0.088163 0" euler="0 0 -2.501923">
        <joint name="RR_coxa" type="hinge" axis="0 0 1"
               range="-2.0944 2.0944"/>
        <geom name="RR_coxa" type="capsule"
              fromto="0 0 0 0 0.041700 0" size="0.012"
              rgba="0.9 0.6 0.1 1" mass="0.064"/>

        <body name="RR_femur" pos="0 0.041700 0">
          <joint name="RR_femur" type="hinge" axis="1 0 0"
                 range="-2.0944 2.0944"/>
          <geom name="RR_femur" type="capsule"
                fromto="0 0 0 0 0 -0.080000" size="0.01"
                rgba="0.8 0.7 0.2 1" mass="0.064"/>

          <body name="RR_tibia" pos="0 0 -0.080000">
            <joint name="RR_tibia" type="hinge" axis="1 0 0"
                   range="-2.0944 2.0944"/>
            <geom name="RR_tibia" type="capsule"
                  fromto="0 0 0 0 0 -0.133780" size="0.008"
                  rgba="0.7 0.3 0.2 1" mass="0.064"/>
            <geom name="RR_foot" type="sphere"
                  pos="0 0 -0.133780" size="0.008"
                  rgba="0.9 0.9 0.9 1" mass="0.001"/>
            <site name="RR_foot_site" pos="0 0 -0.133780"
                  type="sphere" size="0.0240" rgba="1 0 0 0.3"/>
          </body>
        </body>
      </body>
    </body>
  </worldbody>

  <actuator>
    <position name="LF_coxa_act" joint="LF_coxa" kp="20.0" ctrlrange="-2.0944 2.0944" forcerange="-3.430 3.430"/>
    <position name="LF_femur_act" joint="LF_femur" kp="20.0" ctrlrange="-2.0944 2.0944" forcerange="-3.430 3.430"/>
    <position name="LF_tibia_act" joint="LF_tibia" kp="20.0" ctrlrange="-2.0944 2.0944" forcerange="-3.430 3.430"/>
    <position name="LM_coxa_act" joint="LM_coxa" kp="20.0" ctrlrange="-2.0944 2.0944" forcerange="-3.430 3.430"/>
    <position name="LM_femur_act" joint="LM_femur" kp="20.0" ctrlrange="-2.0944 2.0944" forcerange="-3.430 3.430"/>
    <position name="LM_tibia_act" joint="LM_tibia" kp="20.0" ctrlrange="-2.0944 2.0944" forcerange="-3.430 3.430"/>
    <position name="LR_coxa_act" joint="LR_coxa" kp="20.0" ctrlrange="-2.0944 2.0944" forcerange="-3.430 3.430"/>
    <position name="LR_femur_act" joint="LR_femur" kp="20.0" ctrlrange="-2.0944 2.0944" forcerange="-3.430 3.430"/>
    <position name="LR_tibia_act" joint="LR_tibia" kp="20.0" ctrlrange="-2.0944 2.0944" forcerange="-3.430 3.430"/>
    <position name="RF_coxa_act" joint="RF_coxa" kp="20.0" ctrlrange="-2.0944 2.0944" forcerange="-3.430 3.430"/>
    <position name="RF_femur_act" joint="RF_femur" kp="20.0" ctrlrange="-2.0944 2.0944" forcerange="-3.430 3.430"/>
    <position name="RF_tibia_act" joint="RF_tibia" kp="20.0" ctrlrange="-2.0944 2.0944" forcerange="-3.430 3.430"/>
    <position name="RM_coxa_act" joint="RM_coxa" kp="20.0" ctrlrange="-2.0944 2.0944" forcerange="-3.430 3.430"/>
    <position name="RM_femur_act" joint="RM_femur" kp="20.0" ctrlrange="-2.0944 2.0944" forcerange="-3.430 3.430"/>
    <position name="RM_tibia_act" joint="RM_tibia" kp="20.0" ctrlrange="-2.0944 2.0944" forcerange="-3.430 3.430"/>
    <position name="RR_coxa_act" joint="RR_coxa" kp="20.0" ctrlrange="-2.0944 2.0944" forcerange="-3.430 3.430"/>
    <position name="RR_femur_act" joint="RR_femur" kp="20.0" ctrlrange="-2.0944 2.0944" forcerange="-3.430 3.430"/>
    <position name="RR_tibia_act" joint="RR_tibia" kp="20.0" ctrlrange="-2.0944 2.0944" forcerange="-3.430 3.430"/>
  </actuator>

  <sensor>
    <!-- Body IMU -->
    <framequat name="body_quat" objtype="body" objname="body"/>
    <framelinvel name="body_linvel" objtype="body" objname="body"/>
    <frameangvel name="body_angvel" objtype="body" objname="body"/>
    <accelerometer name="imu_accel" site="body_imu"/>
    <gyro name="imu_gyro" site="body_imu"/>

    <!-- Foot contact forces -->
    <touch name="LF_contact" site="LF_foot_site"/>
    <touch name="LM_contact" site="LM_foot_site"/>
    <touch name="LR_contact" site="LR_foot_site"/>
    <touch name="RF_contact" site="RF_foot_site"/>
    <touch name="RM_contact" site="RM_foot_site"/>
    <touch name="RR_contact" site="RR_foot_site"/>

    <!-- Joint positions and velocities -->
    <jointpos name="LF_coxa_pos" joint="LF_coxa"/>
    <jointvel name="LF_coxa_vel" joint="LF_coxa"/>
    <jointpos name="LF_femur_pos" joint="LF_femur"/>
    <jointvel name="LF_femur_vel" joint="LF_femur"/>
    <jointpos name="LF_tibia_pos" joint="LF_tibia"/>
    <jointvel name="LF_tibia_vel" joint="LF_tibia"/>
    <jointpos name="LM_coxa_pos" joint="LM_coxa"/>
    <jointvel name="LM_coxa_vel" joint="LM_coxa"/>
    <jointpos name="LM_femur_pos" joint="LM_femur"/>
    <jointvel name="LM_femur_vel" joint="LM_femur"/>
    <jointpos name="LM_tibia_pos" joint="LM_tibia"/>
    <jointvel name="LM_tibia_vel" joint="LM_tibia"/>
    <jointpos name="LR_coxa_pos" joint="LR_coxa"/>
    <jointvel name="LR_coxa_vel" joint="LR_coxa"/>
    <jointpos name="LR_femur_pos" joint="LR_femur"/>
    <jointvel name="LR_femur_vel" joint="LR_femur"/>
    <jointpos name="LR_tibia_pos" joint="LR_tibia"/>
    <jointvel name="LR_tibia_vel" joint="LR_tibia"/>
    <jointpos name="RF_coxa_pos" joint="RF_coxa"/>
    <jointvel name="RF_coxa_vel" joint="RF_coxa"/>
    <jointpos name="RF_femur_pos" joint="RF_femur"/>
    <jointvel name="RF_femur_vel" joint="RF_femur"/>
    <jointpos name="RF_tibia_pos" joint="RF_tibia"/>
    <jointvel name="RF_tibia_vel" joint="RF_tibia"/>
    <jointpos name="RM_coxa_pos" joint="RM_coxa"/>
    <jointvel name="RM_coxa_vel" joint="RM_coxa"/>
    <jointpos name="RM_femur_pos" joint="RM_femur"/>
    <jointvel name="RM_femur_vel" joint="RM_femur"/>
    <jointpos name="RM_tibia_pos" joint="RM_tibia"/>
    <jointvel name="RM_tibia_vel" joint="RM_tibia"/>
    <jointpos name="RR_coxa_pos" joint="RR_coxa"/>
    <jointvel name="RR_coxa_vel" joint="RR_coxa"/>
    <jointpos name="RR_femur_pos" joint="RR_femur"/>
    <jointvel name="RR_femur_vel" joint="RR_femur"/>
    <jointpos name="RR_tibia_pos" joint="RR_tibia"/>
    <jointvel name="RR_tibia_vel" joint="RR_tibia"/>
  </sensor>

  <keyframe>
    <key name="stand" qpos="0.000000 0.000000 0.150000 1.000000 0.000000 0.000000 0.000000 0.000000 1.361812 -1.286688 0.000000 1.361812 -1.286688 0.000000 1.361812 -1.286688 0.000000 1.361812 -1.286688 0.000000 1.361812 -1.286688 0.000000 1.361812 -1.286688"
         ctrl="0.000000 1.361812 -1.286688 0.000000 1.361812 -1.286688 0.000000 1.361812 -1.286688 0.000000 1.361812 -1.286688 0.000000 1.361812 -1.286688 0.000000 1.361812 -1.286688"/>
  </keyframe>

</mujoco>
